Workbook

Sheet کابینت زمینی
A1: ردیف: | B1: کابینت زمینی | C1: کف | E1: بدنه | G1: طبقه | I1: قید | K1: عرض 3میل | L1: طول 3میل | M1: عرض درب: | N1: ارتفاع درب:
A2: 1- | B2: 80 | C2: 58 | D2: =B2 -> 80 | E2: 58 | F2: 73.4 | G2: 55 | H2: =B2-3.2 -> 76.8 | I2: 7 | J2: =B2-3.2 -> 76.8 | K2: =D2-1.6 -> 78.4 | L2: =F2+1.6-0.8 -> 74.2 | M2: =IF(AND(B2>=10,B2<=50), B2-0.2, IF(AND(B2>50,B2<=100),B2/2-0.2, IF(AND(B2>100,B2<=150),B2/3-0.2, ""))) -> 39.8 | N2: 73.4
C3: نوار: | D3: نوار: | E3: نوار: | F3: نوار: | G3: نوار: | H3: نوار: | I3: نوار: | J3: نوار: | M3: نوار: | N3: نوار:
C4: 0 | D4: 1 | E4: 0 | F4: 1 | G4: 0 | H4: 1 | I4: 0 | J4: 0
C5: تعداد: | D5: 1 | E5: تعداد: | F5: 2 | G5: تعداد: | H5: 1 | I5: تعداد: | J5: 1 | K5: تعداد: | L5: 1 | M5: تعداد: | N5: =IF(AND(B2>=10,B2<=50),1,IF(AND(B2>50,B2<=100),2,IF(AND(B2>100,B2<=150),3,""))) -> 2
A11: 2 | B11: کابینت زمینی | C11: کف | E11: بدنه | G11: طبقه | I11: قید | K11: عرض 3میل | L11: طول 3میل | M11: عرض درب: | N11: ارتفاع درب:
B12: 100 | C12: 58 | D12: =B12 -> 100 | E12: 58 | F12: 73.4 | G12: 55 | H12: =B12-3.2 -> 96.8 | I12: 7 | J12: =B12-3.2 -> 96.8 | K12: =D12-1.6 -> 98.4 | L12: =F12+1.6-0.8 -> 74.2 | M12: =IF(AND(B12>=10,B12<=50), B12-0.2, IF(AND(B12>50,B12<=100),B12/2-0.2, IF(AND(B12>100,B12<=150),B12/3-0.2, ""))) -> 49.8 | N12: 73.4
C13: نوار: | D13: نوار: | E13: نوار: | F13: نوار: | G13: نوار: | H13: نوار: | I13: نوار: | J13: نوار: | M13: نوار: | N13: نوار:
C14: 0 | D14: 1 | E14: 0 | F14: 1 | G14: 0 | H14: 1 | I14: 0 | J14: 0
C15: تعداد: | D15: 1 | E15: تعداد: | F15: 2 | G15: تعداد: | H15: 1 | I15: تعداد: | J15: 1 | K15: تعداد: | L15: 1 | M15: تعداد: | N15: =IF(AND(B12>=10,B12<=50),1,IF(AND(B12>50,B12<=100),2,IF(AND(B12>100,B12<=150),3,""))) -> 2
A20: 3 | B20: کابینت زمینی | C20: کف | E20: بدنه | G20: طبقه | I20: قید | K20: عرض 3میل | L20: طول 3میل | M20: عرض درب: | N20: ارتفاع درب:
B21: 98 | C21: 58 | D21: =B21 -> 98 | E21: 58 | F21: 73.4 | G21: 55 | H21: =B21-3.2 -> 94.8 | I21: 7 | J21: =B21-3.2 -> 94.8 | K21: =D21-1.6 -> 96.4 | L21: =F21+1.6-0.8 -> 74.2 | M21: =IF(AND(B21>=10,B21<=50), B21-0.2, IF(AND(B21>50,B21<=100),B21/2-0.2, IF(AND(B21>100,B21<=150),B21/3-0.2, ""))) -> 48.8 | N21: 73.4
C22: نوار: | D22: نوار: | E22: نوار: | F22: نوار: | G22: نوار: | H22: نوار: | I22: نوار: | J22: نوار: | M22: نوار: | N22: نوار:
C23: 0 | D23: 1 | E23: 0 | F23: 1 | G23: 0 | H23: 1 | I23: 0 | J23: 0
C24: تعداد: | D24: 1 | E24: تعداد: | F24: 2 | G24: تعداد: | H24: 1 | I24: تعداد: | J24: 1 | K24: تعداد: | L24: 1 | M24: تعداد: | N24: =IF(AND(B21>=10,B21<=50),1,IF(AND(B21>50,B21<=100),2,IF(AND(B21>100,B21<=150),3,""))) -> 2
A30: 4 | B30: کابینت زمینی | C30: کف | E30: بدنه | G30: طبقه | I30: قید | K30: عرض 3میل | L30: طول 3میل | M30: عرض درب: | N30: ارتفاع درب:
B31: 100 | C31: 58 | D31: =B31 -> 100 | E31: 58 | F31: 73.4 | G31: 55 | H31: =B31-3.2 -> 96.8 | I31: 7 | J31: =B31-3.2 -> 96.8 | K31: =D31-1.6 -> 98.4 | L31: =F31+1.6-0.8 -> 74.2 | M31: =IF(AND(B31>=10,B31<=50), B31-0.2, IF(AND(B31>50,B31<=100),B31/2-0.2, IF(AND(B31>100,B31<=150),B31/3-0.2, ""))) -> 49.8 | N31: 73.4
C32: نوار: | D32: نوار: | E32: نوار: | F32: نوار: | G32: نوار: | H32: نوار: | I32: نوار: | J32: نوار: | M32: نوار: | N32: نوار:
C33: 0 | D33: 1 | E33: 0 | F33: 1 | G33: 0 | H33: 1 | I33: 0 | J33: 0
C34: تعداد: | D34: 1 | E34: تعداد: | F34: 2 | G34: تعداد: | H34: 1 | I34: تعداد: | J34: 1 | K34: تعداد: | L34: 1 | M34: تعداد: | N34: =IF(AND(B31>=10,B31<=50),1,IF(AND(B31>50,B31<=100),2,IF(AND(B31>100,B31<=150),3,""))) -> 2
A38: 5 | B38: کابینت زمینی | C38: کف | E38: بدنه | G38: طبقه | I38: قید | K38: عرض 3میل | L38: طول 3میل | M38: عرض درب: | N38: ارتفاع درب:
B39: 98 | C39: 58 | D39: =B39 -> 98 | E39: 58 | F39: 73.4 | G39: 55 | H39: =B39-3.2 -> 94.8 | I39: 7 | J39: =B39-3.2 -> 94.8 | K39: =D39-1.6 -> 96.4 | L39: =F39+1.6-0.8 -> 74.2 | M39: =IF(AND(B39>=10,B39<=50), B39-0.2, IF(AND(B39>50,B39<=100),B39/2-0.2, IF(AND(B39>100,B39<=150),B39/3-0.2, ""))) -> 48.8 | N39: 73.4
C40: نوار: | D40: نوار: | E40: نوار: | F40: نوار: | G40: نوار: | H40: نوار: | I40: نوار: | J40: نوار: | M40: نوار: | N40: نوار:
C41: 0 | D41: 1 | E41: 0 | F41: 1 | G41: 0 | H41: 1 | I41: 0 | J41: 0
C42: تعداد: | D42: 1 | E42: تعداد: | F42: 2 | G42: تعداد: | H42: 1 | I42: تعداد: | J42: 1 | K42: تعداد: | L42: 1 | M42: تعداد: | N42: =IF(AND(B39>=10,B39<=50),1,IF(AND(B39>50,B39<=100),2,IF(AND(B39>100,B39<=150),3,""))) -> 2
A46: 6 | B46: کابینت زمینی | C46: کف | E46: بدنه | G46: طبقه | I46: قید | K46: عرض 3میل | L46: طول 3میل | M46: عرض درب: | N46: ارتفاع درب:
B47: 98 | C47: 58 | D47: =B47 -> 98 | E47: 58 | F47: 73.4 | G47: 55 | H47: =B47-3.2 -> 94.8 | I47: 7 | J47: =B47-3.2 -> 94.8 | K47: =D47-1.6 -> 96.4 | L47: =F47+1.6-0.8 -> 74.2 | M47: =IF(AND(B47>=10,B47<=50), B47-0.2, IF(AND(B47>50,B47<=100),B47/2-0.2, IF(AND(B47>100,B47<=150),B47/3-0.2, ""))) -> 48.8 | N47: 73.4
C48: نوار: | D48: نوار: | E48: نوار: | F48: نوار: | G48: نوار: | H48: نوار: | I48: نوار: | J48: نوار: | M48: نوار: | N48: نوار:
C49: 0 | D49: 1 | E49: 0 | F49: 1 | G49: 0 | H49: 1 | I49: 0 | J49: 0
C50: تعداد: | D50: 1 | E50: تعداد: | F50: 2 | G50: تعداد: | H50: 1 | I50: تعداد: | J50: 1 | K50: تعداد: | L50: 1 | M50: تعداد: | N50: =IF(AND(B47>=10,B47<=50),1,IF(AND(B47>50,B47<=100),2,IF(AND(B47>100,B47<=150),3,""))) -> 2
A54: 7 | B54: کابینت زمینی | C54: کف | E54: بدنه | G54: طبقه | I54: قید | K54: عرض 3میل | L54: طول 3میل | M54: عرض درب: | N54: ارتفاع درب:
B55: 30 | C55: 58 | D55: =B55 -> 30 | E55: 58 | F55: 73.4 | G55: 55 | H55: =B55-3.2 -> 26.8 | I55: 7 | J55: =B55-3.2 -> 26.8 | K55: =D55-1.6 -> 28.4 | L55: =F55+1.6-0.8 -> 74.2 | M55: =IF(AND(B55>=10,B55<=50), B55-0.2, IF(AND(B55>50,B55<=100),B55/2-0.2, IF(AND(B55>100,B55<=150),B55/3-0.2, ""))) -> 29.8 | N55: 73.4
C56: نوار: | D56: نوار: | E56: نوار: | F56: نوار: | G56: نوار: | H56: نوار: | I56: نوار: | J56: نوار: | M56: نوار: | N56: نوار:
C57: 0 | D57: 1 | E57: 0 | F57: 1 | G57: 0 | H57: 1 | I57: 0 | J57: 0
C58: تعداد: | D58: 1 | E58: تعداد: | F58: 2 | G58: تعداد: | H58: 1 | I58: تعداد: | J58: 1 | K58: تعداد: | L58: 1 | M58: تعداد: | N58: =IF(AND(B55>=10,B55<=50),1,IF(AND(B55>50,B55<=100),2,IF(AND(B55>100,B55<=150),3,""))) -> 1
A62: 8 | B62: کابینت زمینی | C62: کف | E62: بدنه | G62: طبقه | I62: قید | K62: عرض 3میل | L62: طول 3میل | M62: عرض درب: | N62: ارتفاع درب:
B63: 98 | C63: 58 | D63: =B63 -> 98 | E63: 58 | F63: 73.4 | G63: 55 | H63: =B63-3.2 -> 94.8 | I63: 7 | J63: =B63-3.2 -> 94.8 | K63: =D63-1.6 -> 96.4 | L63: =F63+1.6-0.8 -> 74.2 | M63: =IF(AND(B63>=10,B63<=50), B63-0.2, IF(AND(B63>50,B63<=100),B63/2-0.2, IF(AND(B63>100,B63<=150),B63/3-0.2, ""))) -> 48.8 | N63: 73.4
C64: نوار: | D64: نوار: | E64: نوار: | F64: نوار: | G64: نوار: | H64: نوار: | I64: نوار: | J64: نوار: | M64: نوار: | N64: نوار:
C65: 0 | D65: 1 | E65: 0 | F65: 1 | G65: 0 | H65: 1 | I65: 0 | J65: 0
C66: تعداد: | D66: 1 | E66: تعداد: | F66: 2 | G66: تعداد: | H66: 1 | I66: تعداد: | J66: 1 | K66: تعداد: | L66: 1 | M66: تعداد: | N66: =IF(AND(B63>=10,B63<=50),1,IF(AND(B63>50,B63<=100),2,IF(AND(B63>100,B63<=150),3,""))) -> 2
...

Sheet آنالیز زمینی
B1: ردیف: | I1: نام یونیت:
B2: 1 | C2: توضیحات | D2: تعداد | E2: نوار | F2: عرض | G2: نوار | H2: طول | I2: ='کابینت زمینی'!B2 -> 80 | J2: 3میل | K2: تعداد | L2: عرض | M2: طول
D3: ='کابینت زمینی'!D5 -> 1 | E3: ='کابینت زمینی'!C4 -> 0 | F3: ='کابینت زمینی'!C2 -> 58 | G3: ='کابینت زمینی'!D4 -> 1 | H3: ='کابینت زمینی'!D2 -> 80 | I3: کف: | K3: ='کابینت زمینی'!L5 -> 1 | L3: ='کابینت زمینی'!K2 -> 78.4 | M3: ='کابینت زمینی'!L2 -> 74.2 | O3: طول | P3: عرض | Q3: تعداد | R3: موارد | T3: طول | U3: عرض | V3: تعداد | W3: موارد
D4: ='کابینت زمینی'!F5 -> 2 | E4: ='کابینت زمینی'!E4 -> 0 | F4: ='کابینت زمینی'!E2 -> 58 | G4: ='کابینت زمینی'!F4 -> 1 | H4: ='کابینت زمینی'!F2 -> 73.4 | I4: بدونه: | O4: =H3 -> 80 | P4: =F3 -> 58 | Q4: =D3 -> 1 | R4: safid366 | T4: =M3 -> 74.2 | U4: =L3 -> 78.4 | V4: =K3 -> 1 | W4: 3mil
D5: ='کابینت زمینی'!H5 -> 1 | E5: ='کابینت زمینی'!G4 -> 0 | F5: ='کابینت زمینی'!G2 -> 55 | G5: ='کابینت زمینی'!H4 -> 1 | H5: ='کابینت زمینی'!H2 -> 76.8 | I5: طبقه: | O5: =H4 -> 73.4 | P5: =F4 -> 58 | Q5: =D4 -> 2 | R5: safid366 | T5: =M11 -> 74.2 | U5: =L11 -> 98.4 | V5: =K11 -> 1 | W5: 3mil
D6: ='کابینت زمینی'!J5 -> 1 | E6: ='کابینت زمینی'!I4 -> 0 | F6: ='کابینت زمینی'!I2 -> 7 | G6: ='کابینت زمینی'!J4 -> 0 | H6: ='کابینت زمینی'!J2 -> 76.8 | I6: قید: | O6: =H5 -> 76.8 | P6: =F5 -> 55 | Q6: =D5 -> 1 | R6: safid366 | T6: =M19 -> 74.2 | U6: =L19 -> 96.4 | V6: =K19 -> 1 | W6: 3mil
O7: =H6 -> 76.8 | P7: =F6 -> 7 | Q7: =D6 -> 1 | R7: safid366 | T7: =M27 -> 74.2 | U7: =L27 -> 98.4 | V7: =K27 -> 1 | W7: 3mil
O8: =H11 -> 100 | P8: =F11 -> 58 | Q8: =D11 -> 1 | R8: safid366 | T8: =M35 -> 74.2 | U8: =L35 -> 96.4 | V8: =K35 -> 1 | W8: 3mil
I9: نام یونیت: | O9: =H12 -> 73.4 | P9: =F12 -> 58 | Q9: =D12 -> 2 | R9: safid366 | T9: =M43 -> 74.2 | U9: =L43 -> 96.4 | V9: =K43 -> 1 | W9: 3mil
B10: 2 | C10: توضیحات | D10: تعداد | E10: نوار | F10: عرض | G10: نوار | H10: طول | I10: ='کابینت زمینی'!B12 -> 100 | J10: 3میل | K10: تعداد | L10: عرض | M10: طول | O10: =H13 -> 96.8 | P10: =F13 -> 55 | Q10: =D13 -> 1 | R10: safid366 | T10: =M51 -> 74.2 | U10: =L51 -> 28.4 | V10: =K51 -> 1 | W10: 3mil
D11: ='کابینت زمینی'!D15 -> 1 | E11: ='کابینت زمینی'!C14 -> 0 | F11: ='کابینت زمینی'!C12 -> 58 | G11: ='کابینت زمینی'!D14 -> 1 | H11: ='کابینت زمینی'!D12 -> 100 | I11: کف: | K11: ='کابینت زمینی'!L15 -> 1 | L11: ='کابینت زمینی'!K12 -> 98.4 | M11: ='کابینت زمینی'!L12 -> 74.2 | O11: =H14 -> 96.8 | P11: =F14 -> 7 | Q11: =D14 -> 1 | R11: safid366 | T11: =M60 -> 74.2 | U11: =L60 -> 96.4 | V11: =K60 -> 1 | W11: 3mil
D12: ='کابینت زمینی'!F15 -> 2 | E12: ='کابینت زمینی'!E14 -> 0 | F12: ='کابینت زمینی'!E12 -> 58 | G12: ='کابینت زمینی'!F14 -> 1 | H12: ='کابینت زمینی'!F12 -> 73.4 | I12: بدونه: | O12: =H19 -> 98 | P12: =F19 -> 58 | Q12: =D19 -> 1 | R12: safid366 | T12: =M68 -> 74.2 | U12: =L68 -> 96.4 | V12: =K68 -> 1 | W12: 3mil
D13: ='کابینت زمینی'!H15 -> 1 | E13: ='کابینت زمینی'!G14 -> 0 | F13: ='کابینت زمینی'!G12 -> 55 | G13: ='کابینت زمینی'!H14 -> 1 | H13: ='کابینت زمینی'!H12 -> 96.8 | I13: طبقه: | O13: =H20 -> 73.4 | P13: =F20 -> 58 | Q13: =D19 -> 1 | R13: safid366 | T13: =M76 -> 74.2 | U13: =L76 -> 98.4 | V13: =K76 -> 0 | W13: 3mil
D14: ='کابینت زمینی'!J15 -> 1 | E14: ='کابینت زمینی'!I14 -> 0 | F14: ='کابینت زمینی'!I12 -> 7 | G14: ='کابینت زمینی'!J14 -> 0 | H14: ='کابینت زمینی'!J12 -> 96.8 | I14: قید: | O14: =H21 -> 94.8 | P14: =F21 -> 55 | Q14: =D21 -> 1 | R14: safid366 | T14: =M84 -> 74.2 | U14: =L84 -> 96.4 | V14: =K84 -> 0 | W14: 3mil
O15: =H22 -> 94.8 | P15: =F22 -> 7 | Q15: =D22 -> 1 | R15: safid366
O16: =H27 -> 100 | P16: =F27 -> 58 | Q16: =D27 -> 1 | R16: safid366
I17: نام یونیت: | O17: =H28 -> 73.4 | P17: =F28 -> 58 | Q17: =D28 -> 2 | R17: safid366
B18: 3 | C18: توضیحات | D18: تعداد | E18: نوار | F18: عرض | G18: نوار | H18: طول | I18: ='کابینت زمینی'!B21 -> 98 | J18: 3میل | K18: تعداد | L18: عرض | M18: طول | O18: =H29 -> 96.8 | P18: =F29 -> 55 | Q18: =D29 -> 1 | R18: safid366
D19: ='کابینت زمینی'!D24 -> 1 | E19: ='کابینت زمینی'!C23 -> 0 | F19: ='کابینت زمینی'!C21 -> 58 | G19: ='کابینت زمینی'!D23 -> 1 | H19: ='کابینت زمینی'!D21 -> 98 | I19: کف: | K19: ='کابینت زمینی'!L24 -> 1 | L19: ='کابینت زمینی'!K21 -> 96.4 | M19: ='کابینت زمینی'!L21 -> 74.2 | O19: =H30 -> 96.8 | P19: =F30 -> 7 | Q19: =D30 -> 1 | R19: safid366
D20: ='کابینت زمینی'!F24 -> 2 | E20: ='کابینت زمینی'!E23 -> 0 | F20: ='کابینت زمینی'!E21 -> 58 | G20: ='کابینت زمینی'!F23 -> 1 | H20: ='کابینت زمینی'!F21 -> 73.4 | I20: بدونه: | O20: =H35 -> 98 | P20: =F35 -> 58 | Q20: =D35 -> 1 | R20: safid366
D21: ='کابینت زمینی'!H24 -> 1 | E21: ='کابینت زمینی'!G23 -> 0 | F21: ='کابینت زمینی'!G21 -> 55 | G21: ='کابینت زمینی'!H23 -> 1 | H21: ='کابینت زمینی'!H21 -> 94.8 | I21: طبقه: | O21: =H36 -> 73.4 | P21: =F36 -> 58 | Q21: =D36 -> 2 | R21: safid366 | T21: طول | U21: عرض | V21: تعداد | W21: موارد
D22: ='کابینت زمینی'!J24 -> 1 | E22: ='کابینت زمینی'!I23 -> 0 | F22: ='کابینت زمینی'!I21 -> 7 | G22: ='کابینت زمینی'!J23 -> 0 | H22: ='کابینت زمینی'!J21 -> 94.8 | I22: قید: | O22: =H37 -> 94.8 | P22: =F37 -> 55 | Q22: =D37 -> 1 | R22: safid366 | T22: ='کابینت زمینی'!N2 -> 73.4 | U22: ='کابینت زمینی'!M2 -> 39.8 | V22: ='کابینت زمینی'!N5 -> 2
O23: =H38 -> 94.8 | P23: =F38 -> 7 | Q23: =D38 -> 1 | R23: safid366 | T23: ='کابینت زمینی'!N12 -> 73.4 | U23: ='کابینت زمینی'!M12 -> 49.8 | V23: ='کابینت زمینی'!N15 -> 2
O24: =H43 -> 98 | P24: =F43 -> 58 | Q24: =D43 -> 1 | R24: safid366 | T24: ='کابینت زمینی'!N21 -> 73.4 | U24: ='کابینت زمینی'!M21 -> 48.8 | V24: ='کابینت زمینی'!N24 -> 2
I25: نام یونیت: | O25: =H44 -> 73.4 | P25: =F44 -> 58 | Q25: =D44 -> 2 | R25: safid366 | T25: ='کابینت زمینی'!N31 -> 73.4 | U25: ='کابینت زمینی'!M31 -> 49.8 | V25: ='کابینت زمینی'!N34 -> 2
B26: 4 | C26: توضیحات | D26: تعداد | E26: نوار | F26: عرض | G26: نوار | H26: طول | I26: ='کابینت زمینی'!B31 -> 100 | J26: 3میل | K26: تعداد | L26: عرض | M26: طول | O26: =H45 -> 94.8 | P26: =F45 -> 55 | Q26: =D45 -> 1 | R26: safid366 | T26: ='کابینت زمینی'!N39 -> 73.4 | U26: ='کابینت زمینی'!M39 -> 48.8 | V26: ='کابینت زمینی'!N42 -> 2
D27: ='کابینت زمینی'!D34 -> 1 | E27: ='کابینت زمینی'!C33 -> 0 | F27: ='کابینت زمینی'!C31 -> 58 | G27: ='کابینت زمینی'!D33 -> 1 | H27: ='کابینت زمینی'!D31 -> 100 | I27: کف: | K27: ='کابینت زمینی'!L34 -> 1 | L27: ='کابینت زمینی'!K31 -> 98.4 | M27: ='کابینت زمینی'!L31 -> 74.2 | O27: =H46 -> 94.8 | P27: =F46 -> 7 | Q27: =D46 -> 1 | R27: safid366 | T27: ='کابینت زمینی'!N47 -> 73.4 | U27: ='کابینت زمینی'!M47 -> 48.8 | V27: ='کابینت زمینی'!N50 -> 2
D28: ='کابینت زمینی'!F34 -> 2 | E28: ='کابینت زمینی'!E33 -> 0 | F28: ='کابینت زمینی'!E31 -> 58 | G28: ='کابینت زمینی'!F33 -> 1 | H28: ='کابینت زمینی'!F31 -> 73.4 | I28: بدونه: | O28: =H51 -> 30 | P28: =F51 -> 58 | Q28: =D51 -> 1 | R28: safid366 | T28: ='کابینت زمینی'!N55 -> 73.4 | U28: ='کابینت زمینی'!M55 -> 29.8 | V28: ='کابینت زمینی'!N58 -> 1
D29: ='کابینت زمینی'!H34 -> 1 | E29: ='کابینت زمینی'!G33 -> 0 | F29: ='کابینت زمینی'!G31 -> 55 | G29: ='کابینت زمینی'!H33 -> 1 | H29: ='کابینت زمینی'!H31 -> 96.8 | I29: طبقه: | O29: =H52 -> 73.4 | P29: =F52 -> 58 | Q29: =D52 -> 2 | R29: safid366 | T29: ='کابینت زمینی'!N63 -> 73.4 | U29: ='کابینت زمینی'!M63 -> 48.8 | V29: ='کابینت زمینی'!N66 -> 2
D30: ='کابینت زمینی'!J34 -> 1 | E30: ='کابینت زمینی'!I33 -> 0 | F30: ='کابینت زمینی'!I31 -> 7 | G30: ='کابینت زمینی'!J33 -> 0 | H30: ='کابینت زمینی'!J31 -> 96.8 | I30: قید: | O30: =H53 -> 26.8 | P30: =F53 -> 55 | Q30: =D53 -> 1 | R30: safid366 | T30: ='کابینت زمینی'!N71 -> 73.4 | U30: ='کابینت زمینی'!M71 -> 48.8 | V30: ='کابینت زمینی'!N74 -> 2
O31: =H54 -> 26.8 | P31: =F54 -> 7 | Q31: =D54 -> 1 | R31: safid366 | T31: ='کابینت زمینی'!N79 -> 73.4 | U31: ='کابینت زمینی'!M79 -> 49.8 | V31: ='کابینت زمینی'!N82 -> 2
O32: =H60 -> 98 | P32: =F60 -> 58 | Q32: =D60 -> 1 | R32: safid366 | T32: ='کابینت زمینی'!N87 -> 73.4 | U32: ='کابینت زمینی'!M87 -> 48.8 | V32: ='کابینت زمینی'!N90 -> 2
I33: نام یونیت: | O33: =H61 -> 73.4 | P33: =F61 -> 58 | Q33: =D61 -> 2 | R33: safid366
B34: 5 | C34: توضیحات | D34: تعداد | E34: نوار | F34: عرض | G34: نوار | H34: طول | I34: ='کابینت زمینی'!B39 -> 98 | J34: 3میل | K34: تعداد | L34: عرض | M34: طول | O34: =H45 -> 94.8 | P34: =F45 -> 55 | Q34: =D45 -> 1 | R34: safid366
D35: ='کابینت زمینی'!D42 -> 1 | E35: ='کابینت زمینی'!C41 -> 0 | F35: ='کابینت زمینی'!C39 -> 58 | G35: ='کابینت زمینی'!D41 -> 1 | H35: ='کابینت زمینی'!D39 -> 98 | I35: کف: | K35: ='کابینت زمینی'!L42 -> 1 | L35: ='کابینت زمینی'!K39 -> 96.4 | M35: ='کابینت زمینی'!L39 -> 74.2 | O35: =H46 -> 94.8 | P35: =F46 -> 7 | Q35: =D46 -> 1 | R35: safid366
D36: ='کابینت زمینی'!F42 -> 2 | E36: ='کابینت زمینی'!E41 -> 0 | F36: ='کابینت زمینی'!E39 -> 58 | G36: ='کابینت زمینی'!F41 -> 1 | H36: ='کابینت زمینی'!F39 -> 73.4 | I36: بدونه: | O36: =H51 -> 30 | P36: =F51 -> 58 | Q36: =D51 -> 1 | R36: safid366
D37: ='کابینت زمینی'!H42 -> 1 | E37: ='کابینت زمینی'!G41 -> 0 | F37: ='کابینت زمینی'!G39 -> 55 | G37: ='کابینت زمینی'!H41 -> 1 | H37: ='کابینت زمینی'!H39 -> 94.8 | I37: طبقه: | O37: =H52 -> 73.4 | P37: =F52 -> 58 | Q37: =D52 -> 2 | R37: safid366
D38: ='کابینت زمینی'!J42 -> 1 | E38: ='کابینت زمینی'!I41 -> 0 | F38: ='کابینت زمینی'!I39 -> 7 | G38: ='کابینت زمینی'!J41 -> 0 | H38: ='کابینت زمینی'!J39 -> 94.8 | I38: قید: | O38: =H53 -> 26.8 | P38: =F53 -> 55 | Q38: =D53 -> 1 | R38: safid366
O39: =H54 -> 26.8 | P39: =F54 -> 7 | Q39: =D54 -> 1 | R39: safid366
O40: =H60 -> 98 | P40: =F60 -> 58 | Q40: =D60 -> 1 | R40: safid366
...

Sheet کابینت هوایی
A1: ردیف
A2: 1 | B2: کابینت هوایی | C2: بدنه | E2: کف | G2: تاق | I2: طبقه | K2: قید | M2: عرض3 میل | N2: طول3 میل | O2: عرض درب | P2: طول درب
B3: 60 | C3: 35 | D3: 90 | E3: 35 | F3: =B3-3.2 -> 56.8 | G3: =C3-2 -> 33 | H3: =B3-3.2 -> 56.8 | I3: =E3-3 -> 32 | J3: =F3 -> 56.8 | K3: 7 | L3: =B3-3.2 -> 56.8 | M3: =F3+1.6 -> 58.4 | N3: =D3-0.8 -> 89.2 | O3: =IF(AND(B3>=10,B3<=50), B3-0.2, IF(AND(B3>50,B3<=100),B3/2-0.2, IF(AND(B3>100,B3<=150),B3/3-0.2, ""))) -> 29.8 | P3: 92
C4: نوار | D4: نوار | E4: نوار | F4: نوار | G4: نوار | H4: نوار | I4: نوار | J4: نوار | K4: نوار | L4: نوار
C5: 1 | D5: 1 | E5: 0 | F5: 1 | G5: 0 | H5: 1 | I5: 0 | J5: 1 | K5: 0 | L5: 0
C6: تعداد: | D6: 2 | E6: تعداد: | F6: 1 | G6: تعداد: | H6: 1 | I6: تعداد: | J6: 1 | K6: تعداد | L6: 1 | M6: تعداد | N6: 1 | O6: تعداد: | P6: =IF(AND(B3>=10,B3<=50),1,IF(AND(B3>50,B3<=100),2,IF(AND(B3>100,B3<=150),3,""))) -> 2
A9: 2 | B9: کابینت هوایی | C9: بدنه | E9: کف | G9: تاق | I9: طبقه | K9: قید | M9: عرض3 میل | N9: طول3 میل | O9: عرض درب | P9: طول درب
B10: 84 | C10: 35 | D10: 100 | E10: 35 | F10: =B10-3.2 -> 80.8 | G10: =C10-2 -> 33 | H10: =B10-3.2 -> 80.8 | I10: =E10-3 -> 32 | J10: =F10 -> 80.8 | K10: 7 | L10: =B10-3.2 -> 80.8 | M10: =F10+1.6 -> 82.4 | N10: =D10-0.8 -> 99.2 | O10: =IF(AND(B10>=10,B10<=50), B10-0.2, IF(AND(B10>50,B10<=100),B10/2-0.2, IF(AND(B10>100,B10<=150),B10/3-0.2, ""))) -> 41.8 | P10: 92
C11: نوار | D11: نوار | E11: نوار | F11: نوار | G11: نوار | H11: نوار | I11: نوار | J11: نوار | K11: نوار | L11: نوار
C12: 1 | D12: 1 | E12: 0 | F12: 1 | G12: 0 | H12: 1 | I12: 0 | J12: 1 | K12: 0 | L12: 0
C13: تعداد: | D13: 2 | E13: تعداد: | F13: 1 | G13: تعداد: | H13: 1 | I13: تعداد: | J13: 1 | K13: تعداد | L13: 1 | M13: تعداد | N13: 1 | O13: تعداد: | P13: =IF(AND(B10>=10,B10<=50),1,IF(AND(B10>50,B10<=100),2,IF(AND(B10>100,B10<=150),3,""))) -> 2
A16: 3 | B16: کابینت هوایی | C16: بدنه | E16: کف | G16: تاق | I16: طبقه | K16: قید | M16: عرض3 میل | N16: طول3 میل | O16: عرض درب | P16: طول درب
B17: 80 | C17: 35 | D17: 90 | E17: 35 | F17: =B17-3.2 -> 76.8 | G17: =C17-2 -> 33 | H17: =B17-3.2 -> 76.8 | I17: =E17-3 -> 32 | J17: =F17 -> 76.8 | K17: 7 | L17: =B17-3.2 -> 76.8 | M17: =F17+1.6 -> 78.4 | N17: =D17-0.8 -> 89.2 | O17: =IF(AND(B17>=10,B17<=50), B17-0.2, IF(AND(B17>50,B17<=100),B17/2-0.2, IF(AND(B17>100,B17<=150),B17/3-0.2, ""))) -> 39.8 | P17: 92
C18: نوار | D18: نوار | E18: نوار | F18: نوار | G18: نوار | H18: نوار | I18: نوار | J18: نوار | K18: نوار | L18: نوار
C19: 1 | D19: 1 | E19: 0 | F19: 1 | G19: 0 | H19: 1 | I19: 0 | J19: 1 | K19: 0 | L19: 0
C20: تعداد: | D20: 2 | E20: تعداد: | F20: 1 | G20: تعداد: | H20: 1 | I20: تعداد: | J20: 1 | K20: تعداد | L20: 1 | M20: تعداد | N20: 1 | O20: تعداد: | P20: =IF(AND(B17>=10,B17<=50),1,IF(AND(B17>50,B17<=100),2,IF(AND(B17>100,B17<=150),3,""))) -> 2
A23: 4 | B23: کابینت هوایی | C23: بدنه | E23: کف | G23: تاق | I23: طبقه | K23: قید | M23: عرض3 میل | N23: طول3 میل | O23: عرض درب | P23: طول درب
B24: 84 | C24: 35 | D24: 90 | E24: 35 | F24: =B24-3.2 -> 80.8 | G24: =C24-2 -> 33 | H24: =B24-3.2 -> 80.8 | I24: =E24-3 -> 32 | J24: =F24 -> 80.8 | K24: 7 | L24: =B24-3.2 -> 80.8 | M24: =F24+1.6 -> 82.4 | N24: =D24-0.8 -> 89.2 | O24: =IF(AND(B24>=10,B24<=50), B24-0.2, IF(AND(B24>50,B24<=100),B24/2-0.2, IF(AND(B24>100,B24<=150),B24/3-0.2, ""))) -> 41.8 | P24: 92
C25: نوار | D25: نوار | E25: نوار | F25: نوار | G25: نوار | H25: نوار | I25: نوار | J25: نوار | K25: نوار | L25: نوار
C26: 1 | D26: 1 | E26: 0 | F26: 1 | G26: 0 | H26: 1 | I26: 0 | J26: 1 | K26: 0 | L26: 0
C27: تعداد: | D27: 2 | E27: تعداد: | F27: 1 | G27: تعداد: | H27: 1 | I27: تعداد: | J27: 1 | K27: تعداد | L27: 1 | M27: تعداد | N27: 1 | O27: تعداد: | P27: =IF(AND(B24>=10,B24<=50),1,IF(AND(B24>50,B24<=100),2,IF(AND(B24>100,B24<=150),3,""))) -> 2
A30: 5 | B30: کابینت هوایی | C30: بدنه | E30: کف | G30: تاق | I30: طبقه | K30: قید | M30: عرض3 میل | N30: طول3 میل | O30: عرض درب | P30: طول درب
B31: 84 | C31: 35 | D31: 90 | E31: 35 | F31: =B31-3.2 -> 80.8 | G31: =C31-2 -> 33 | H31: =B31-3.2 -> 80.8 | I31: =E31-3 -> 32 | J31: =F31 -> 80.8 | K31: 7 | L31: =B31-3.2 -> 80.8 | M31: =F31+1.6 -> 82.4 | N31: =D31-0.8 -> 89.2 | O31: =IF(AND(B31>=10,B31<=50), B31-0.2, IF(AND(B31>50,B31<=100),B31/2-0.2, IF(AND(B31>100,B31<=150),B31/3-0.2, ""))) -> 41.8 | P31: 92
C32: نوار | D32: نوار | E32: نوار | F32: نوار | G32: نوار | H32: نوار | I32: نوار | J32: نوار | K32: نوار | L32: نوار
C33: 1 | D33: 1 | E33: 0 | F33: 1 | G33: 0 | H33: 1 | I33: 0 | J33: 1 | K33: 0 | L33: 0
C34: تعداد: | D34: 2 | E34: تعداد: | F34: 1 | G34: تعداد: | H34: 1 | I34: تعداد: | J34: 1 | K34: تعداد | L34: 1 | M34: تعداد | N34: 1 | O34: تعداد: | P34: =IF(AND(B31>=10,B31<=50),1,IF(AND(B31>50,B31<=100),2,IF(AND(B31>100,B31<=150),3,""))) -> 2
A37: 6 | B37: کابینت هوایی | C37: بدنه | E37: کف | G37: تاق | I37: طبقه | K37: قید | M37: عرض3 میل | N37: طول3 میل | O37: عرض درب | P37: طول درب
B38: 84 | C38: 35 | D38: 90 | E38: 35 | F38: =B38-3.2 -> 80.8 | G38: =C38-2 -> 33 | H38: =B38-3.2 -> 80.8 | I38: =E38-3 -> 32 | J38: =F38 -> 80.8 | K38: 7 | L38: =B38-3.2 -> 80.8 | M38: =F38+1.6 -> 82.4 | N38: =D38-0.8 -> 89.2 | O38: =IF(AND(B38>=10,B38<=50), B38-0.2, IF(AND(B38>50,B38<=100),B38/2-0.2, IF(AND(B38>100,B38<=150),B38/3-0.2, ""))) -> 41.8 | P38: 92
C39: نوار | D39: نوار | E39: نوار | F39: نوار | G39: نوار | H39: نوار | I39: نوار | J39: نوار | K39: نوار | L39: نوار
C40: 1 | D40: 1 | E40: 0 | F40: 1 | G40: 0 | H40: 1 | I40: 0 | J40: 1 | K40: 0 | L40: 0
C41: تعداد: | D41: 2 | E41: تعداد: | F41: 1 | G41: تعداد: | H41: 1 | I41: تعداد: | J41: 1 | K41: تعداد | L41: 1 | M41: تعداد | N41: 1 | O41: تعداد: | P41: =IF(AND(B38>=10,B38<=50),1,IF(AND(B38>50,B38<=100),2,IF(AND(B38>100,B38<=150),3,""))) -> 2
A44: 7 | B44: کابینت هوایی | C44: بدنه | E44: کف | G44: تاق | I44: طبقه | K44: قید | M44: عرض3 میل | N44: طول3 میل | O44: عرض درب | P44: طول درب
B45: 84 | C45: 35 | D45: 90 | E45: 35 | F45: =B45-3.2 -> 80.8 | G45: =C45-2 -> 33 | H45: =B45-3.2 -> 80.8 | I45: =E45-3 -> 32 | J45: =F45 -> 80.8 | K45: 7 | L45: =B45-3.2 -> 80.8 | M45: =F45+1.6 -> 82.4 | N45: =D45-0.8 -> 89.2 | O45: =IF(AND(B45>=10,B45<=50), B45-0.2, IF(AND(B45>50,B45<=100),B45/2-0.2, IF(AND(B45>100,B45<=150),B45/3-0.2, ""))) -> 41.8 | P45: 92
C46: نوار | D46: نوار | E46: نوار | F46: نوار | G46: نوار | H46: نوار | I46: نوار | J46: نوار | K46: نوار | L46: نوار
C47: 1 | D47: 1 | E47: 0 | F47: 1 | G47: 0 | H47: 1 | I47: 0 | J47: 1 | K47: 0 | L47: 0
C48: تعداد: | D48: 2 | E48: تعداد: | F48: 1 | G48: تعداد: | H48: 1 | I48: تعداد: | J48: 1 | K48: تعداد | L48: 1 | M48: تعداد | N48: 1 | O48: تعداد: | P48: =IF(AND(B45>=10,B45<=50),1,IF(AND(B45>50,B45<=100),2,IF(AND(B45>100,B45<=150),3,""))) -> 2
A51: 8 | B51: کابینت هوایی | C51: بدنه | E51: کف | G51: تاق | I51: طبقه | K51: قید | M51: عرض3 میل | N51: طول3 میل | O51: عرض درب | P51: طول درب
B52: 84 | C52: 35 | D52: 90 | E52: 35 | F52: =B52-3.2 -> 80.8 | G52: =C52-2 -> 33 | H52: =B52-3.2 -> 80.8 | I52: =E52-3 -> 32 | J52: =F52 -> 80.8 | K52: 7 | L52: =B52-3.2 -> 80.8 | M52: =F52+1.6 -> 82.4 | N52: =D52-0.8 -> 89.2 | O52: =IF(AND(B52>=10,B52<=50), B52-0.2, IF(AND(B52>50,B52<=100),B52/2-0.2, IF(AND(B52>100,B52<=150),B52/3-0.2, ""))) -> 41.8 | P52: 92
C53: نوار | D53: نوار | E53: نوار | F53: نوار | G53: نوار | H53: نوار | I53: نوار | J53: نوار | K53: نوار | L53: نوار
C54: 1 | D54: 1 | E54: 0 | F54: 1 | G54: 0 | H54: 1 | I54: 0 | J54: 1 | K54: 0 | L54: 0
...

Sheet آنالیز هوایی
B1: ردیف
I2: نام یونیت:
B3: 1 | C3: توضیحات | D3: تعداد | E3: نوار | F3: عرض | G3: نوار | H3: طول | I3: ='کابینت هوایی'!B3 -> 60 | L3: طول | M3: عرض | N3: تعداد | O3: موارد | Q3: طول | R3: عرض | S3: تعداد | T3: موارد
D4: ='کابینت هوایی'!D6 -> 2 | E4: ='کابینت هوایی'!C5 -> 1 | F4: ='کابینت هوایی'!C3 -> 35 | G4: ='کابینت هوایی'!D5 -> 1 | H4: ='کابینت هوایی'!D3 -> 90 | I4: بدنه | L4: =H4 -> 90 | M4: =F4 -> 35 | N4: =D4 -> 2 | O4: safid366 | Q4: ='کابینت هوایی'!N3 -> 89.2 | R4: ='کابینت هوایی'!M3 -> 58.4 | S4: ='کابینت هوایی'!N6 -> 1 | T4: 3mil
D5: ='کابینت هوایی'!F6 -> 1 | E5: ='کابینت هوایی'!E5 -> 0 | F5: ='کابینت هوایی'!E3 -> 35 | G5: ='کابینت هوایی'!F5 -> 1 | H5: ='کابینت هوایی'!F3 -> 56.8 | I5: کف | L5: =H5 -> 56.8 | M5: =F5 -> 35 | N5: =D5 -> 1 | O5: safid366 | Q5: ='کابینت هوایی'!N10 -> 99.2 | R5: ='کابینت هوایی'!M10 -> 82.4 | S5: ='کابینت هوایی'!N13 -> 1 | T5: 3mil
D6: ='کابینت هوایی'!H6 -> 1 | E6: ='کابینت هوایی'!G5 -> 0 | F6: ='کابینت هوایی'!G3 -> 33 | G6: ='کابینت هوایی'!H5 -> 1 | H6: ='کابینت هوایی'!H3 -> 56.8 | I6: تاق | L6: =H6 -> 56.8 | M6: =F6 -> 33 | N6: =D6 -> 1 | O6: safid366 | Q6: ='کابینت هوایی'!N17 -> 89.2 | R6: ='کابینت هوایی'!M17 -> 78.4 | S6: ='کابینت هوایی'!N20 -> 1 | T6: 3mil
D7: ='کابینت هوایی'!J6 -> 1 | E7: ='کابینت هوایی'!I5 -> 0 | F7: ='کابینت هوایی'!I3 -> 32 | G7: ='کابینت هوایی'!J5 -> 1 | H7: ='کابینت هوایی'!J3 -> 56.8 | I7: طبقه | L7: =H7 -> 56.8 | M7: =F7 -> 32 | N7: =D7 -> 1 | O7: safid366 | Q7: ='کابینت هوایی'!N24 -> 89.2 | R7: ='کابینت هوایی'!M24 -> 82.4 | S7: ='کابینت هوایی'!N27 -> 1 | T7: 3mil
D8: ='کابینت هوایی'!L6 -> 1 | E8: ='کابینت هوایی'!K5 -> 0 | F8: ='کابینت هوایی'!K3 -> 7 | G8: ='کابینت هوایی'!L5 -> 0 | H8: ='کابینت هوایی'!L3 -> 56.8 | I8: قید | L8: =H8 -> 56.8 | M8: =F8 -> 7 | N8: =D8 -> 1 | O8: safid366 | Q8: ='کابینت هوایی'!N31 -> 89.2 | R8: ='کابینت هوایی'!M31 -> 82.4 | S8: ='کابینت هوایی'!N34 -> 1 | T8: 3mil
L9: =H12 -> 100 | M9: =F12 -> 35 | N9: =D12 -> 2 | O9: safid366 | Q9: ='کابینت هوایی'!N38 -> 89.2 | R9: ='کابینت هوایی'!M38 -> 82.4 | S9: ='کابینت هوایی'!N41 -> 1 | T9: 3mil
B10: 2 | I10: نام یونیت: | L10: =H13 -> 80.8 | M10: =F13 -> 35 | N10: =D13 -> 1 | O10: safid366 | Q10: ='کابینت هوایی'!N45 -> 89.2 | R10: ='کابینت هوایی'!M45 -> 82.4 | S10: ='کابینت هوایی'!N48 -> 1 | T10: 3mil
C11: توضیحات | D11: تعداد | E11: نوار | F11: عرض | G11: نوار | H11: طول | I11: ='کابینت هوایی'!B10 -> 84 | L11: =H14 -> 80.8 | M11: =F14 -> 33 | N11: =D14 -> 1 | O11: safid366 | Q11: ='کابینت هوایی'!N52 -> 89.2 | R11: ='کابینت هوایی'!M52 -> 82.4 | S11: ='کابینت هوایی'!N55 -> 1 | T11: 3mil
D12: ='کابینت هوایی'!D13 -> 2 | E12: ='کابینت هوایی'!C12 -> 1 | F12: ='کابینت هوایی'!C10 -> 35 | G12: ='کابینت هوایی'!D12 -> 1 | H12: ='کابینت هوایی'!D10 -> 100 | I12: بدنه | L12: =H15 -> 80.8 | M12: =F15 -> 32 | N12: =D15 -> 1 | O12: safid366 | Q12: ='کابینت هوایی'!N59 -> 89.2 | R12: ='کابینت هوایی'!M59 -> 82.4 | S12: ='کابینت هوایی'!N62 -> 1 | T12: 3mil
D13: ='کابینت هوایی'!F13 -> 1 | E13: ='کابینت هوایی'!E12 -> 0 | F13: ='کابینت هوایی'!E10 -> 35 | G13: ='کابینت هوایی'!F12 -> 1 | H13: ='کابینت هوایی'!F10 -> 80.8 | I13: کف | L13: =H16 -> 80.8 | M13: =F16 -> 7 | N13: =D16 -> 1 | O13: safid366 | Q13: ='کابینت هوایی'!N66 -> 89.2 | R13: ='کابینت هوایی'!M66 -> 82.4 | S13: ='کابینت هوایی'!N69 -> 1 | T13: 3mil
D14: ='کابینت هوایی'!H13 -> 1 | E14: ='کابینت هوایی'!G12 -> 0 | F14: ='کابینت هوایی'!G10 -> 33 | G14: ='کابینت هوایی'!H12 -> 1 | H14: ='کابینت هوایی'!H10 -> 80.8 | I14: تاق | L14: =H20 -> 90 | M14: =F20 -> 35 | N14: =D20 -> 2 | O14: safid366 | Q14: ='کابینت هوایی'!N73 -> 89.2 | R14: ='کابینت هوایی'!M73 -> 82.4 | S14: ='کابینت هوایی'!N76 -> 1 | T14: 3mil
D15: ='کابینت هوایی'!L13 -> 1 | E15: ='کابینت هوایی'!I12 -> 0 | F15: ='کابینت هوایی'!I10 -> 32 | G15: ='کابینت هوایی'!J12 -> 1 | H15: ='کابینت هوایی'!J10 -> 80.8 | I15: طبقه | L15: =H21 -> 76.8 | M15: =F21 -> 35 | N15: =D21 -> 1 | O15: safid366 | Q15: ='کابینت هوایی'!N80 -> 49.2 | R15: ='کابینت هوایی'!M80 -> 82.4 | S15: ='کابینت هوایی'!N83 -> 1 | T15: 3mil
D16: ='کابینت هوایی'!L13 -> 1 | E16: ='کابینت هوایی'!K12 -> 0 | F16: ='کابینت هوایی'!K10 -> 7 | G16: ='کابینت هوایی'!L12 -> 0 | H16: ='کابینت هوایی'!L10 -> 80.8 | I16: قید | L16: =H22 -> 76.8 | M16: =F22 -> 33 | N16: =D22 -> 1 | O16: safid366 | Q16: ='کابینت هوایی'!N87 -> 89.2 | R16: ='کابینت هوایی'!M87 -> 82.4 | S16: ='کابینت هوایی'!N90 -> 1 | T16: 3mil
L17: =H23 -> 76.8 | M17: =F23 -> 32 | N17: =D23 -> 1 | O17: safid366 | Q17: ='کابینت هوایی'!N94 -> 89.2 | R17: ='کابینت هوایی'!M94 -> 82.4 | S17: ='کابینت هوایی'!N97 -> 1 | T17: 3mil
I18: نام یونیت: | L18: =H24 -> 76.8 | M18: =F24 -> 7 | N18: =D24 -> 1 | O18: safid366 | Q18: ='کابینت هوایی'!N101 -> 89.2 | R18: ='کابینت هوایی'!M101 -> 82.4 | S18: ='کابینت هوایی'!N104 -> 1 | T18: 3mil
B19: 3 | C19: توضیحات | D19: تعداد | E19: نوار | F19: عرض | G19: نوار | H19: طول | I19: ='کابینت هوایی'!B17 -> 80 | L19: =H28 -> 90 | M19: =F28 -> 35 | N19: =D28 -> 2 | O19: safid366 | Q19: ='کابینت هوایی'!N108 -> 89.2 | R19: ='کابینت هوایی'!M108 -> 82.4 | S19: ='کابینت هوایی'!N111 -> 1 | T19: 3mil
D20: ='کابینت هوایی'!D20 -> 2 | E20: ='کابینت هوایی'!C19 -> 1 | F20: ='کابینت هوایی'!C17 -> 35 | G20: ='کابینت هوایی'!D19 -> 1 | H20: ='کابینت هوایی'!D17 -> 90 | I20: بدنه | L20: =H29 -> 80.8 | M20: =F29 -> 35 | N20: =D29 -> 1 | O20: safid366 | Q20: ='کابینت هوایی'!N115 -> 89.2 | R20: ='کابینت هوایی'!M115 -> 82.4 | S20: ='کابینت هوایی'!N118 -> 1 | T20: 3mil
D21: ='کابینت هوایی'!H20 -> 1 | E21: ='کابینت هوایی'!E19 -> 0 | F21: ='کابینت هوایی'!E17 -> 35 | G21: ='کابینت هوایی'!F19 -> 1 | H21: ='کابینت هوایی'!F17 -> 76.8 | I21: کف | L21: =H30 -> 80.8 | M21: =F30 -> 33 | N21: =D30 -> 1 | O21: safid366 | Q21: ='کابینت هوایی'!N122 -> 89.2 | R21: ='کابینت هوایی'!M122 -> 82.4 | S21: ='کابینت هوایی'!N125 -> 1 | T21: 3mil
D22: ='کابینت هوایی'!H20 -> 1 | E22: ='کابینت هوایی'!G19 -> 0 | F22: ='کابینت هوایی'!G17 -> 33 | G22: ='کابینت هوایی'!H19 -> 1 | H22: ='کابینت هوایی'!H17 -> 76.8 | I22: تاق | L22: =H31 -> 80.8 | M22: =F31 -> 32 | N22: =D31 -> 1 | O22: safid366 | Q22: ='کابینت هوایی'!N129 -> 89.2 | R22: ='کابینت هوایی'!M129 -> 82.4 | S22: ='کابینت هوایی'!N132 -> 1 | T22: 3mil
D23: ='کابینت هوایی'!J20 -> 1 | E23: ='کابینت هوایی'!I19 -> 0 | F23: ='کابینت هوایی'!I17 -> 32 | G23: ='کابینت هوایی'!J19 -> 1 | H23: ='کابینت هوایی'!J17 -> 76.8 | I23: طبقه | L23: =H32 -> 80.8 | M23: =F32 -> 7 | N23: =D32 -> 1 | O23: safid366 | Q23: ='کابینت هوایی'!N136 -> 89.2 | R23: ='کابینت هوایی'!M136 -> 33.4 | S23: ='کابینت هوایی'!N139 -> 1 | T23: 3mil
D24: ='کابینت هوایی'!L20 -> 1 | E24: ='کابینت هوایی'!K19 -> 0 | F24: ='کابینت هوایی'!K17 -> 7 | G24: ='کابینت هوایی'!L19 -> 0 | H24: ='کابینت هوایی'!L17 -> 76.8 | I24: قید | L24: =H36 -> 90 | M24: =F36 -> 35 | N24: =D36 -> 2 | O24: safid366
L25: =H37 -> 80.8 | M25: =F37 -> 35 | N25: =D37 -> 1 | O25: safid366
I26: نام یونیت: | L26: =H38 -> 80.8 | M26: =F38 -> 33 | N26: =D38 -> 1 | O26: safid366
B27: 4 | C27: توضیحات | D27: تعداد | E27: نوار | F27: عرض | G27: نوار | H27: طول | I27: ='کابینت هوایی'!B24 -> 84 | L27: =H39 -> 80.8 | M27: =F39 -> 32 | N27: =D39 -> 1 | O27: safid366
D28: ='کابینت هوایی'!D34 -> 2 | E28: ='کابینت هوایی'!C26 -> 1 | F28: ='کابینت هوایی'!C24 -> 35 | G28: ='کابینت هوایی'!D26 -> 1 | H28: ='کابینت هوایی'!D24 -> 90 | I28: بدنه | L28: =H40 -> 80.8 | M28: =F40 -> 7 | N28: =D40 -> 1 | O28: safid366 | Q28: طول | R28: عرض | S28: تعداد | T28: موارد
D29: ='کابینت هوایی'!F27 -> 1 | E29: ='کابینت هوایی'!E26 -> 0 | F29: ='کابینت هوایی'!E24 -> 35 | G29: ='کابینت هوایی'!F26 -> 1 | H29: ='کابینت هوایی'!F24 -> 80.8 | I29: کف | L29: =H44 -> 90 | M29: =F44 -> 35 | N29: =D44 -> 2 | O29: safid366 | Q29: ='کابینت هوایی'!P3 -> 92 | R29: ='کابینت هوایی'!O3 -> 29.8 | S29: ='کابینت هوایی'!P6 -> 2
D30: ='کابینت هوایی'!H27 -> 1 | E30: ='کابینت هوایی'!G26 -> 0 | F30: ='کابینت هوایی'!G24 -> 33 | G30: ='کابینت هوایی'!H26 -> 1 | H30: ='کابینت هوایی'!H24 -> 80.8 | I30: تاق | L30: =H45 -> 80.8 | M30: =F45 -> 35 | N30: =D45 -> 1 | O30: safid366 | Q30: ='کابینت هوایی'!P10 -> 92 | R30: ='کابینت هوایی'!O10 -> 41.8 | S30: ='کابینت هوایی'!P13 -> 2
D31: ='کابینت هوایی'!J27 -> 1 | E31: ='کابینت هوایی'!I26 -> 0 | F31: ='کابینت هوایی'!I24 -> 32 | G31: ='کابینت هوایی'!J26 -> 1 | H31: ='کابینت هوایی'!J24 -> 80.8 | I31: طبقه | L31: =H46 -> 80.8 | M31: =F46 -> 33 | N31: =D46 -> 1 | O31: safid366 | Q31: ='کابینت هوایی'!P17 -> 92 | R31: ='کابینت هوایی'!O17 -> 39.8 | S31: ='کابینت هوایی'!P20 -> 2
D32: ='کابینت هوایی'!L27 -> 1 | E32: ='کابینت هوایی'!K26 -> 0 | F32: ='کابینت هوایی'!K24 -> 7 | G32: ='کابینت هوایی'!L26 -> 0 | H32: ='کابینت هوایی'!L24 -> 80.8 | I32: قید | L32: =H47 -> 80.8 | M32: =F47 -> 32 | N32: =D47 -> 1 | O32: safid366 | Q32: ='کابینت هوایی'!P24 -> 92 | R32: ='کابینت هوایی'!O24 -> 41.8 | S32: ='کابینت هوایی'!P27 -> 2
L33: =H48 -> 80.8 | M33: =F48 -> 7 | N33: =D48 -> 1 | O33: safid366 | Q33: ='کابینت هوایی'!P31 -> 92 | R33: ='کابینت هوایی'!O31 -> 41.8 | S33: ='کابینت هوایی'!P34 -> 2
I34: نام یونیت: | L34: =H52 -> 90 | M34: =F52 -> 35 | N34: =D52 -> 2 | O34: safid366 | Q34: ='کابینت هوایی'!P38 -> 92 | R34: ='کابینت هوایی'!O38 -> 41.8 | S34: ='کابینت هوایی'!P41 -> 2
B35: 5 | C35: توضیحات | D35: تعداد | E35: نوار | F35: عرض | G35: نوار | H35: طول | I35: ='کابینت هوایی'!B31 -> 84 | L35: =H53 -> 80.8 | M35: =F53 -> 35 | N35: =D53 -> 1 | O35: safid366 | Q35: ='کابینت هوایی'!P45 -> 92 | R35: ='کابینت هوایی'!O45 -> 41.8 | S35: ='کابینت هوایی'!P48 -> 2
D36: ='کابینت هوایی'!D34 -> 2 | E36: ='کابینت هوایی'!C33 -> 1 | F36: ='کابینت هوایی'!C31 -> 35 | G36: ='کابینت هوایی'!D33 -> 1 | H36: ='کابینت هوایی'!D31 -> 90 | I36: بدنه | L36: =H54 -> 80.8 | M36: =F54 -> 33 | N36: =D54 -> 1 | O36: safid366 | Q36: ='کابینت هوایی'!P52 -> 92 | R36: ='کابینت هوایی'!O52 -> 41.8 | S36: ='کابینت هوایی'!P55 -> 2
D37: ='کابینت هوایی'!F34 -> 1 | E37: ='کابینت هوایی'!E33 -> 0 | F37: ='کابینت هوایی'!E31 -> 35 | G37: ='کابینت هوایی'!F33 -> 1 | H37: ='کابینت هوایی'!F31 -> 80.8 | I37: کف | L37: =H55 -> 80.8 | M37: =F55 -> 32 | N37: =D55 -> 1 | O37: safid366 | Q37: ='کابینت هوایی'!P59 -> 92 | R37: ='کابینت هوایی'!O59 -> 41.8 | S37: ='کابینت هوایی'!P62 -> 2
D38: ='کابینت هوایی'!H34 -> 1 | E38: ='کابینت هوایی'!G33 -> 0 | F38: ='کابینت هوایی'!G31 -> 33 | G38: ='کابینت هوایی'!H33 -> 1 | H38: ='کابینت هوایی'!H31 -> 80.8 | I38: تاق | L38: =H60 -> 90 | M38: =F60 -> 35 | N38: =D60 -> 2 | O38: safid366 | Q38: ='کابینت هوایی'!P66 -> 92 | R38: ='کابینت هوایی'!O66 -> 41.8 | S38: ='کابینت هوایی'!P69 -> 2
D39: ='کابینت هوایی'!J34 -> 1 | E39: ='کابینت هوایی'!I33 -> 0 | F39: ='کابینت هوایی'!I31 -> 32 | G39: ='کابینت هوایی'!J33 -> 1 | H39: ='کابینت هوایی'!J31 -> 80.8 | I39: طبقه | L39: =H61 -> 80.8 | M39: =F61 -> 35 | N39: =D61 -> 1 | O39: safid366 | Q39: ='کابینت هوایی'!P73 -> 92 | R39: ='کابینت هوایی'!O73 -> 41.8 | S39: ='کابینت هوایی'!P76 -> 2
D40: ='کابینت هوایی'!L34 -> 1 | E40: ='کابینت هوایی'!K33 -> 0 | F40: ='کابینت هوایی'!K31 -> 7 | G40: ='کابینت هوایی'!L33 -> 0 | H40: ='کابینت هوایی'!L31 -> 80.8 | I40: قید | L40: =H62 -> 80.8 | M40: =F62 -> 33 | N40: =D62 -> 1 | O40: safid366 | Q40: ='کابینت هوایی'!P80 -> 92 | R40: ='کابینت هوایی'!O80 -> 41.8 | S40: ='کابینت هوایی'!P83 -> 2
...

Sheet کشو
B3: تعداد | C3: عمق | D3: عرض | E3: ارتفاع | G3: بدنه کشو | I3: جلو کشو | K3: پشت کشو
B4: 1 | C4: 50 | D4: 90 | E4: 50 | G4: طول | H4: =C4-5 -> 45 | I4: طول | J4: =D4-9.1 -> 80.9 | K4: طول | L4: =J4 -> 80.9
G5: عرض | H5: =E4/3-4 -> 12.666667 | I5: عرض | J5: =H5 -> 12.666667 | K5: عرض | L5: =J5-2 -> 10.666667
G6: تعداد | H6: =B4*2 -> 2 | I6: تعداد | J6: =B4 -> 1 | K6: تعداد | L6: =J6 -> 1
